host: codespaces-c89ec1
Building DAG of jobs...
Using shell: /usr/bin/bash
Provided cores: 4
Rules claiming more threads will be scaled down.
Job stats:
job                  count
-----------------  -------
all                      1
run_fedX_query           1
run_hefquin_query        1
run_sparql_query         1
total                    4

Select jobs to execute...
Execute 3 jobs...

[Mon Mar 17 20:42:20 2025]
localrule run_sparql_query:
    input: /workspaces/P-TER/virtuoso-opensource-7.2.7, /workspaces/P-TER/virtuoso-opensource-7.2.7/var/lib/virtuoso/db/fedup.ini, queries/q04f.sparql
    output: output/rdfs/Jena/q04f.1.csv, output/rdfs/Jena/q04f.1.json
    jobid: 1
    reason: Updated input files: queries/q04f.sparql
    wildcards: workload=rdfs, query=q04f, run=1
    priority: 50
    resources: tmpdir=/tmp


[Mon Mar 17 20:42:20 2025]
localrule run_fedX_query:
    input: /workspaces/P-TER/virtuoso-opensource-7.2.7, /workspaces/P-TER/virtuoso-opensource-7.2.7/var/lib/virtuoso/db/fedup.ini, /workspaces/P-TER/apache-jena-fuseki-4.9.0, queries/q04f.sparql, config/rdfs/endpoints.txt
    output: output/rdfs/FedX/q04f.1.csv, output/rdfs/FedX/q04f.1.json
    jobid: 2
    reason: Updated input files: queries/q04f.sparql
    wildcards: workload=rdfs, query=q04f, run=1
    priority: 50
    resources: tmpdir=/tmp


[Mon Mar 17 20:42:20 2025]
localrule run_hefquin_query:
    input: /workspaces/P-TER/virtuoso-opensource-7.2.7, /workspaces/P-TER/virtuoso-opensource-7.2.7/var/lib/virtuoso/db/fedup.ini, queries/q04f.sparql
    output: output/rdfs/HefQuin/q04f.1.csv, output/rdfs/HefQuin/q04f.1.json, output/rdfs/HefQuin/q04f.1.txt
    jobid: 3
    reason: Updated input files: queries/q04f.sparql
    wildcards: workload=rdfs, query=q04f, run=1
    priority: 50
    resources: tmpdir=/tmp

Terminating processes on user request, this might take some time.
Traceback (most recent call last):

  File "/usr/local/python/3.12.1/lib/python3.12/site-packages/snakemake/executors/local.py", line 232, in spawn_job
    subprocess.check_call(cmd, shell=True)

  File "/usr/local/python/3.12.1/lib/python3.12/subprocess.py", line 413, in check_call
    raise CalledProcessError(retcode, cmd)

subprocess.CalledProcessError: Command 'cd /workspaces/P-TER && /usr/local/python/3.12.1/bin/python3 -m snakemake --snakefile '/workspaces/P-TER/Snakefile' --target-jobs 'run_hefquin_query:workload=rdfs,query=q04f,run=1' --allowed-rules run_hefquin_query --cores 4 --attempt 1 --force-use-threads  --force --target-files-omit-workdir-adjustment --keep-storage-local-copies --max-inventory-time 0 --nocolor --notemp --no-hooks --nolock --ignore-incomplete --rerun-triggers params software-env input mtime code --conda-frontend 'conda' --shared-fs-usage storage-local-copies source-cache input-output software-deployment persistence sources --wrapper-prefix 'https://github.com/snakemake/snakemake-wrappers/raw/' --latency-wait 5 --scheduler 'greedy' --local-storage-prefix .snakemake/storage --scheduler-solver-path '/usr/local/python/3.12.1/bin' --default-resources base64//dG1wZGlyPXN5c3RlbV90bXBkaXI= --quiet progress rules --mode 'subprocess' --local-groupid 'local'' died with <Signals.SIGINT: 2>.


During handling of the above exception, another exception occurred:


Traceback (most recent call last):

  File "/usr/local/python/3.12.1/lib/python3.12/concurrent/futures/thread.py", line 58, in run
    result = self.fn(*self.args, **self.kwargs)
             ^^^^^^^^^^^^^^^^^^^^^^^^^^^^^^^^^^

  File "/usr/local/python/3.12.1/lib/python3.12/site-packages/snakemake/executors/local.py", line 247, in cached_or_run
    run_func(*args)

  File "/usr/local/python/3.12.1/lib/python3.12/site-packages/snakemake/executors/local.py", line 234, in spawn_job
    raise SpawnedJobError()

snakemake.exceptions.SpawnedJobError

Traceback (most recent call last):

  File "/usr/local/python/3.12.1/lib/python3.12/site-packages/snakemake/executors/local.py", line 232, in spawn_job
    subprocess.check_call(cmd, shell=True)

  File "/usr/local/python/3.12.1/lib/python3.12/subprocess.py", line 413, in check_call
    raise CalledProcessError(retcode, cmd)

subprocess.CalledProcessError: Command 'cd /workspaces/P-TER && /usr/local/python/3.12.1/bin/python3 -m snakemake --snakefile '/workspaces/P-TER/Snakefile' --target-jobs 'run_sparql_query:workload=rdfs,query=q04f,run=1' --allowed-rules run_sparql_query --cores 4 --attempt 1 --force-use-threads  --force --target-files-omit-workdir-adjustment --keep-storage-local-copies --max-inventory-time 0 --nocolor --notemp --no-hooks --nolock --ignore-incomplete --rerun-triggers params software-env input mtime code --conda-frontend 'conda' --shared-fs-usage storage-local-copies source-cache input-output software-deployment persistence sources --wrapper-prefix 'https://github.com/snakemake/snakemake-wrappers/raw/' --latency-wait 5 --scheduler 'greedy' --local-storage-prefix .snakemake/storage --scheduler-solver-path '/usr/local/python/3.12.1/bin' --default-resources base64//dG1wZGlyPXN5c3RlbV90bXBkaXI= --quiet progress rules --mode 'subprocess' --local-groupid 'local'' died with <Signals.SIGINT: 2>.


During handling of the above exception, another exception occurred:


Traceback (most recent call last):

  File "/usr/local/python/3.12.1/lib/python3.12/concurrent/futures/thread.py", line 58, in run
    result = self.fn(*self.args, **self.kwargs)
             ^^^^^^^^^^^^^^^^^^^^^^^^^^^^^^^^^^

  File "/usr/local/python/3.12.1/lib/python3.12/site-packages/snakemake/executors/local.py", line 247, in cached_or_run
    run_func(*args)

  File "/usr/local/python/3.12.1/lib/python3.12/site-packages/snakemake/executors/local.py", line 234, in spawn_job
    raise SpawnedJobError()

snakemake.exceptions.SpawnedJobError

[Mon Mar 17 20:42:27 2025]
[Mon Mar 17 20:42:27 2025]
Error in rule run_hefquin_query:
    jobid: 3
    input: /workspaces/P-TER/virtuoso-opensource-7.2.7, /workspaces/P-TER/virtuoso-opensource-7.2.7/var/lib/virtuoso/db/fedup.ini, queries/q04f.sparql
    output: output/rdfs/HefQuin/q04f.1.csv, output/rdfs/HefQuin/q04f.1.json, output/rdfs/HefQuin/q04f.1.txt

Error in rule run_sparql_query:
    jobid: 1
    input: /workspaces/P-TER/virtuoso-opensource-7.2.7, /workspaces/P-TER/virtuoso-opensource-7.2.7/var/lib/virtuoso/db/fedup.ini, queries/q04f.sparql
    output: output/rdfs/Jena/q04f.1.csv, output/rdfs/Jena/q04f.1.json

Traceback (most recent call last):

  File "/usr/local/python/3.12.1/lib/python3.12/site-packages/snakemake/executors/local.py", line 232, in spawn_job
    subprocess.check_call(cmd, shell=True)

  File "/usr/local/python/3.12.1/lib/python3.12/subprocess.py", line 413, in check_call
    raise CalledProcessError(retcode, cmd)

subprocess.CalledProcessError: Command 'cd /workspaces/P-TER && /usr/local/python/3.12.1/bin/python3 -m snakemake --snakefile '/workspaces/P-TER/Snakefile' --target-jobs 'run_fedX_query:workload=rdfs,query=q04f,run=1' --allowed-rules run_fedX_query --cores 4 --attempt 1 --force-use-threads  --force --target-files-omit-workdir-adjustment --keep-storage-local-copies --max-inventory-time 0 --nocolor --notemp --no-hooks --nolock --ignore-incomplete --rerun-triggers params software-env input mtime code --conda-frontend 'conda' --shared-fs-usage storage-local-copies source-cache input-output software-deployment persistence sources --wrapper-prefix 'https://github.com/snakemake/snakemake-wrappers/raw/' --latency-wait 5 --scheduler 'greedy' --local-storage-prefix .snakemake/storage --scheduler-solver-path '/usr/local/python/3.12.1/bin' --default-resources base64//dG1wZGlyPXN5c3RlbV90bXBkaXI= --quiet progress rules --mode 'subprocess' --local-groupid 'local'' died with <Signals.SIGINT: 2>.


During handling of the above exception, another exception occurred:


Traceback (most recent call last):

  File "/usr/local/python/3.12.1/lib/python3.12/concurrent/futures/thread.py", line 58, in run
    result = self.fn(*self.args, **self.kwargs)
             ^^^^^^^^^^^^^^^^^^^^^^^^^^^^^^^^^^

  File "/usr/local/python/3.12.1/lib/python3.12/site-packages/snakemake/executors/local.py", line 247, in cached_or_run
    run_func(*args)

  File "/usr/local/python/3.12.1/lib/python3.12/site-packages/snakemake/executors/local.py", line 234, in spawn_job
    raise SpawnedJobError()

snakemake.exceptions.SpawnedJobError

[Mon Mar 17 20:42:27 2025]
Error in rule run_fedX_query:
    jobid: 2
    input: /workspaces/P-TER/virtuoso-opensource-7.2.7, /workspaces/P-TER/virtuoso-opensource-7.2.7/var/lib/virtuoso/db/fedup.ini, /workspaces/P-TER/apache-jena-fuseki-4.9.0, queries/q04f.sparql, config/rdfs/endpoints.txt
    output: output/rdfs/FedX/q04f.1.csv, output/rdfs/FedX/q04f.1.json

Complete log: .snakemake/log/2025-03-17T204220.541722.snakemake.log
WorkflowError:
At least one job did not complete successfully.
