host: codespaces-c89ec1
Building DAG of jobs...
Using shell: /usr/bin/bash
Provided cores: 1 (use --cores to define parallelism)
Rules claiming more threads will be scaled down.
Job stats:
job                     count
--------------------  -------
all                         1
run_Fedup_FedX_query        7
total                       8

Select jobs to execute...
Execute 1 jobs...

[Tue Mar 18 19:48:36 2025]
localrule run_Fedup_FedX_query:
    input: /workspaces/P-TER/virtuoso-opensource-7.2.7, /workspaces/P-TER/virtuoso-opensource-7.2.7/var/lib/virtuoso/db/fedup.ini, fedup-queries/q05a.sparql
    output: output/rdfs/FedUp-FedX/q05a.1.csv, output/rdfs/FedUp-FedX/q05a.1.json
    jobid: 401
    reason: Missing output files: output/rdfs/FedUp-FedX/q05a.1.csv
    wildcards: workload=rdfs, query=q05a, run=1
    priority: 50
    resources: tmpdir=/tmp

Terminating processes on user request, this might take some time.
Traceback (most recent call last):

  File "/usr/local/python/3.12.1/lib/python3.12/site-packages/snakemake/executors/local.py", line 232, in spawn_job
    subprocess.check_call(cmd, shell=True)

  File "/usr/local/python/3.12.1/lib/python3.12/subprocess.py", line 413, in check_call
    raise CalledProcessError(retcode, cmd)

subprocess.CalledProcessError: Command 'cd /workspaces/P-TER && /usr/local/python/3.12.1/bin/python3 -m snakemake --snakefile '/workspaces/P-TER/Snakefile' --target-jobs 'run_Fedup_FedX_query:workload=rdfs,query=q05a,run=1' --allowed-rules run_Fedup_FedX_query --cores 1 --attempt 1 --force-use-threads  --force --target-files-omit-workdir-adjustment --keep-storage-local-copies --max-inventory-time 0 --nocolor --notemp --no-hooks --nolock --ignore-incomplete --rerun-triggers mtime input params software-env code --conda-frontend 'conda' --shared-fs-usage persistence storage-local-copies source-cache sources input-output software-deployment --wrapper-prefix 'https://github.com/snakemake/snakemake-wrappers/raw/' --latency-wait 5 --scheduler 'greedy' --local-storage-prefix .snakemake/storage --scheduler-solver-path '/usr/local/python/3.12.1/bin' --default-resources base64//dG1wZGlyPXN5c3RlbV90bXBkaXI= --quiet progress rules --mode 'subprocess' --local-groupid 'local'' died with <Signals.SIGINT: 2>.


During handling of the above exception, another exception occurred:


Traceback (most recent call last):

  File "/usr/local/python/3.12.1/lib/python3.12/concurrent/futures/thread.py", line 58, in run
    result = self.fn(*self.args, **self.kwargs)
             ^^^^^^^^^^^^^^^^^^^^^^^^^^^^^^^^^^

  File "/usr/local/python/3.12.1/lib/python3.12/site-packages/snakemake/executors/local.py", line 247, in cached_or_run
    run_func(*args)

  File "/usr/local/python/3.12.1/lib/python3.12/site-packages/snakemake/executors/local.py", line 234, in spawn_job
    raise SpawnedJobError()

snakemake.exceptions.SpawnedJobError

[Tue Mar 18 20:49:14 2025]
Error in rule run_Fedup_FedX_query:
    jobid: 401
    input: /workspaces/P-TER/virtuoso-opensource-7.2.7, /workspaces/P-TER/virtuoso-opensource-7.2.7/var/lib/virtuoso/db/fedup.ini, fedup-queries/q05a.sparql
    output: output/rdfs/FedUp-FedX/q05a.1.csv, output/rdfs/FedUp-FedX/q05a.1.json

Complete log: .snakemake/log/2025-03-18T194835.751702.snakemake.log
WorkflowError:
At least one job did not complete successfully.
